Workbook

Sheet Справочник номенклатуры
A1: Маркетплейс | B1: Артикул НАШ на площадке | C1: Предмет | D1: Номенклатура (код 1С) | E1: Последний баркод | F1: Тип изделия | G1: Цвет ткани | H1: Ножки | I1: Наименование позиции | J1: Номер позиции | K1: Номер цвета ножек | L1: Универсальный артикул | M1: Предмет для расчета ЗП | N1: Тип изделия
A2: WB | B2: СТ101MEL1 | C2: Стул/сиденье Классика | D2: 90000000 | E2: 2036699042135;2036709153431 | F2: Стул Классика | G2: Melon | H2: =VLOOKUP(K2,'справочник ножек'!A:B,2,FALSE) -> Коричневые ножки | I2: =CONCATENATE(F2," ",G2," ",H2) -> Стул Классика Melon Коричневые ножки | J2: 101 | K2: 1 | L2: =CONCATENATE(J2,G2,K2) -> 101Melon1 | M2: Стул/сиденье | N2: =F2 -> Стул Классика
A3: WB | B3: СТ101ORN2 | C3: Стул/сиденье Классика | D3: 90000000 | E3: 2036708970206;2036709153387 | F3: Стул Классика | G3: Orange | H3: =VLOOKUP(K3,'справочник ножек'!A:B,2,FALSE) -> Белые ножки | I3: =CONCATENATE(F3," ",G3," ",H3) -> Стул Классика Orange Белые ножки | J3: 101 | K3: 2 | L3: =CONCATENATE(J3,G3,K3) -> 101Orange2 | M3: Стул/сиденье | N3: =F3 -> Стул Классика
A4: WB | B4: СТ101MEL3 | C4: Стул/сиденье Классика | D4: 90000000 | E4: 2036709153356 | F4: Стул Классика | G4: Melon | H4: =VLOOKUP(K4,'справочник ножек'!A:B,2,FALSE) -> Черные ножки | I4: =CONCATENATE(F4," ",G4," ",H4) -> Стул Классика Melon Черные ножки | J4: 101 | K4: 3 | L4: =CONCATENATE(J4,G4,K4) -> 101Melon3 | M4: Стул/сиденье | N4: =F4 -> Стул Классика
A5: WB | B5: СТ101BLU1 | C5: Стул/сиденье Классика | D5: 90000000 | E5: 2036709153172 | F5: Стул Классика | G5: Blue | H5: =VLOOKUP(K5,'справочник ножек'!A:B,2,FALSE) -> Коричневые ножки | I5: =CONCATENATE(F5," ",G5," ",H5) -> Стул Классика Blue Коричневые ножки | J5: 101 | K5: 1 | L5: =CONCATENATE(J5,G5,K5) -> 101Blue1 | M5: Стул/сиденье | N5: =F5 -> Стул Классика
A6: WB | B6: СТ101MIN7 | C6: Стул/сиденье Классика | D6: 90000000 | E6: 2036709153196 | F6: Стул Классика | G6: Mint | H6: =VLOOKUP(K6,'справочник ножек'!A:B,2,FALSE) -> Ножки патина серебро | I6: =CONCATENATE(F6," ",G6," ",H6) -> Стул Классика Mint Ножки патина серебро | J6: 101 | K6: 7 | L6: =CONCATENATE(J6,G6,K6) -> 101Mint7 | M6: Стул/сиденье | N6: =F6 -> Стул Классика
A7: WB | B7: СТ101FOR3 | C7: Стул/сиденье Классика | D7: 90000000 | E7: 2036709153301 | F7: Стул Классика | G7: Forest | H7: =VLOOKUP(K7,'справочник ножек'!A:B,2,FALSE) -> Черные ножки | I7: =CONCATENATE(F7," ",G7," ",H7) -> Стул Классика Forest Черные ножки | J7: 101 | K7: 3 | L7: =CONCATENATE(J7,G7,K7) -> 101Forest3 | M7: Стул/сиденье | N7: =F7 -> Стул Классика
A8: WB | B8: СТ101GRE3 | C8: Стул/сиденье Классика | D8: 90000000 | E8: 2036709153417 | F8: Стул Классика | G8: Monsoon | H8: =VLOOKUP(K8,'справочник ножек'!A:B,2,FALSE) -> Черные ножки | I8: =CONCATENATE(F8," ",G8," ",H8) -> Стул Классика Monsoon Черные ножки | J8: 101 | K8: 3 | L8: =CONCATENATE(J8,G8,K8) -> 101Monsoon3 | M8: Стул/сиденье | N8: =F8 -> Стул Классика
A9: WB | B9: СТ101MIN1 | C9: Стул/сиденье Классика | D9: 90000000 | E9: 2036709153141 | F9: Стул Классика | G9: Mint | H9: =VLOOKUP(K9,'справочник ножек'!A:B,2,FALSE) -> Коричневые ножки | I9: =CONCATENATE(F9," ",G9," ",H9) -> Стул Классика Mint Коричневые ножки | J9: 101 | K9: 1 | L9: =CONCATENATE(J9,G9,K9) -> 101Mint1 | M9: Стул/сиденье | N9: =F9 -> Стул Классика
A10: WB | B10: СТ101BIR5 | C10: Стул/сиденье Классика | D10: 90000000 | E10: 2036709153257 | F10: Стул Классика | G10: Biruza | H10: =VLOOKUP(K10,'справочник ножек'!A:B,2,FALSE) -> Ножки прозрачный лак | I10: =CONCATENATE(F10," ",G10," ",H10) -> Стул Классика Biruza Ножки прозрачный лак | J10: 101 | K10: 5 | L10: =CONCATENATE(J10,G10,K10) -> 101Biruza5 | M10: Стул/сиденье | N10: =F10 -> Стул Классика
A11: WB | B11: СТ101ORN1 | C11: Стул/сиденье Классика | D11: 90000000 | E11: 2036709153325 | F11: Стул Классика | G11: Orange | H11: =VLOOKUP(K11,'справочник ножек'!A:B,2,FALSE) -> Коричневые ножки | I11: =CONCATENATE(F11," ",G11," ",H11) -> Стул Классика Orange Коричневые ножки | J11: 101 | K11: 1 | L11: =CONCATENATE(J11,G11,K11) -> 101Orange1 | M11: Стул/сиденье | N11: =F11 -> Стул Классика
A12: WB | B12: СТ101BIR2 | C12: Стул/сиденье Классика | D12: 90000000 | E12: 2036709153448 | F12: Стул Классика | G12: Biruza | H12: =VLOOKUP(K12,'справочник ножек'!A:B,2,FALSE) -> Белые ножки | I12: =CONCATENATE(F12," ",G12," ",H12) -> Стул Классика Biruza Белые ножки | J12: 101 | K12: 2 | L12: =CONCATENATE(J12,G12,K12) -> 101Biruza2 | M12: Стул/сиденье | N12: =F12 -> Стул Классика
A13: WB | B13: СТ101BER3 | C13: Стул/сиденье Классика | D13: 90000000 | E13: 2036709153165 | F13: Стул Классика | G13: Berry | H13: =VLOOKUP(K13,'справочник ножек'!A:B,2,FALSE) -> Черные ножки | I13: =CONCATENATE(F13," ",G13," ",H13) -> Стул Классика Berry Черные ножки | J13: 101 | K13: 3 | L13: =CONCATENATE(J13,G13,K13) -> 101Berry3 | M13: Стул/сиденье | N13: =F13 -> Стул Классика
A14: WB | B14: СТ101MIN3 | C14: Стул/сиденье Классика | D14: 90000000 | E14: 2036709153370 | F14: Стул Классика | G14: Mint | H14: =VLOOKUP(K14,'справочник ножек'!A:B,2,FALSE) -> Черные ножки | I14: =CONCATENATE(F14," ",G14," ",H14) -> Стул Классика Mint Черные ножки | J14: 101 | K14: 3 | L14: =CONCATENATE(J14,G14,K14) -> 101Mint3 | M14: Стул/сиденье | N14: =F14 -> Стул Классика
A15: WB | B15: СТ101GRA3 | C15: Стул/сиденье Классика | D15: 90000000 | E15: 2036709153479 | F15: Стул Классика | G15: Graphite | H15: =VLOOKUP(K15,'справочник ножек'!A:B,2,FALSE) -> Черные ножки | I15: =CONCATENATE(F15," ",G15," ",H15) -> Стул Классика Graphite Черные ножки | J15: 101 | K15: 3 | L15: =CONCATENATE(J15,G15,K15) -> 101Graphite3 | M15: Стул/сиденье | N15: =F15 -> Стул Классика
... A86: WB | B86: CT101MON77 | C86: Стул/сиденье Классика | D86: 90000000 | E86: 2036729930357 | F86: Стул Классика | G86: Monsoon | H86: =VLOOKUP(K86,'справочник ножек'!A:B,2,FALSE) -> Ножки патина серебро | I86: =CONCATENATE(F86," ",G86," ",H86) -> Стул Классика Monsoon Ножки патина серебро | J86: 101 | K86: 7 | L86: =CONCATENATE(J86,G86,K86) -> 101Monsoon7 | M86: Стул/сиденье | N86: =F86 -> Стул Классика
A87: WB | B87: CT101ORN4K | C87: Комплект 2 стульев Классика | D87: 100000000 | E87: 2036791081056 | F87: Комплект Стул Классика | G87: Orange | H87: =VLOOKUP(K87,'справочник ножек'!A:B,2,FALSE) -> Черные ножки с наконечниками | I87: =CONCATENATE(F87," ",G87," ",H87) -> Комплект Стул Классика Orange Черные ножки с наконечниками | J87: К101 | K87: 4 | L87: =CONCATENATE(J87,G87,K87) -> К101Orange4 | M87: Стул/сиденье | N87: =F87 -> Комплект Стул Классика
A88: WB | B88: CT101BEI1K | C88: Комплект 2 стульев Классика | D88: 100000000 | E88: 2036812223861 | F88: Комплект Стул Классика | G88: Beige | H88: =VLOOKUP(K88,'справочник ножек'!A:B,2,FALSE) -> Коричневые ножки | I88: =CONCATENATE(F88," ",G88," ",H88) -> Комплект Стул Классика Beige Коричневые ножки | J88: К101 | K88: 1 | L88: =CONCATENATE(J88,G88,K88) -> К101Beige1 | M88: Стул/сиденье | N88: =F88 -> Комплект Стул Классика
A89: WB | B89: CT101ORN3K | C89: Комплект 2 стульев Классика | D89: 100000000 | E89: 2036816777056 | F89: Комплект Стул Классика | G89: Orange | H89: =VLOOKUP(K89,'справочник ножек'!A:B,2,FALSE) -> Черные ножки | I89: =CONCATENATE(F89," ",G89," ",H89) -> Комплект Стул Классика Orange Черные ножки | J89: К101 | K89: 3 | L89: =CONCATENATE(J89,G89,K89) -> К101Orange3 | M89: Стул/сиденье | N89: =F89 -> Комплект Стул Классика
A90: WB | B90: CT101BIR2K | C90: Комплект 2 стульев Классика | D90: 100000000 | E90: 2036818919270 | F90: Комплект Стул Классика | G90: Biruza | H90: =VLOOKUP(K90,'справочник ножек'!A:B,2,FALSE) -> Белые ножки | I90: =CONCATENATE(F90," ",G90," ",H90) -> Комплект Стул Классика Biruza Белые ножки | J90: К101 | K90: 2 | L90: =CONCATENATE(J90,G90,K90) -> К101Biruza2 | M90: Стул/сиденье | N90: =F90 -> Комплект Стул Классика
A91: WB | B91: CT101BIR3K | C91: Комплект 2 стульев Классика | D91: 100000000 | E91: 2036818923055 | F91: Комплект Стул Классика | G91: Biruza | H91: =VLOOKUP(K91,'справочник ножек'!A:B,2,FALSE) -> Черные ножки | I91: =CONCATENATE(F91," ",G91," ",H91) -> Комплект Стул Классика Biruza Черные ножки | J91: К101 | K91: 3 | L91: =CONCATENATE(J91,G91,K91) -> К101Biruza3 | M91: Стул/сиденье | N91: =F91 -> Комплект Стул Классика
A92: WB | B92: CT101MIN3K | C92: Комплект 2 стульев Классика | D92: 100000000 | E92: 2036819267943 | F92: Комплект Стул Классика | G92: Mint | H92: =VLOOKUP(K92,'справочник ножек'!A:B,2,FALSE) -> Черные ножки | I92: =CONCATENATE(F92," ",G92," ",H92) -> Комплект Стул Классика Mint Черные ножки | J92: К101 | K92: 3 | L92: =CONCATENATE(J92,G92,K92) -> К101Mint3 | M92: Стул/сиденье | N92: =F92 -> Комплект Стул Классика
A93: WB | B93: CT101ORN1K | C93: Комплект 2 стульев Классика | D93: 100000000 | E93: 2036830326278 | F93: Комплект Стул Классика | G93: Orange | H93: =VLOOKUP(K93,'справочник ножек'!A:B,2,FALSE) -> Коричневые ножки | I93: =CONCATENATE(F93," ",G93," ",H93) -> Комплект Стул Классика Orange Коричневые ножки | J93: К101 | K93: 1 | L93: =CONCATENATE(J93,G93,K93) -> К101Orange1 | M93: Стул/сиденье | N93: =F93 -> Комплект Стул Классика
A94: WB | B94: CT101MEL1K | C94: Комплект 2 стульев Классика | D94: 100000000 | E94: 2036830370868 | F94: Комплект Стул Классика | G94: Melon | H94: =VLOOKUP(K94,'справочник ножек'!A:B,2,FALSE) -> Коричневые ножки | I94: =CONCATENATE(F94," ",G94," ",H94) -> Комплект Стул Классика Melon Коричневые ножки | J94: К101 | K94: 1 | L94: =CONCATENATE(J94,G94,K94) -> К101Melon1 | M94: Стул/сиденье | N94: =F94 -> Комплект Стул Классика
A95: WB | B95: CT101MEL2K | C95: Комплект 2 стульев Классика | D95: 100000000 | E95: 2036830390224 | F95: Комплект Стул Классика | G95: Melon | H95: =VLOOKUP(K95,'справочник ножек'!A:B,2,FALSE) -> Белые ножки | I95: =CONCATENATE(F95," ",G95," ",H95) -> Комплект Стул Классика Melon Белые ножки | J95: К101 | K95: 2 | L95: =CONCATENATE(J95,G95,K95) -> К101Melon2 | M95: Стул/сиденье | N95: =F95 -> Комплект Стул Классика
A96: WB | B96: CT101MEL3K | C96: Комплект 2 стульев Классика | D96: 100000000 | E96: 2036830415552 | F96: Комплект Стул Классика | G96: Melon | H96: =VLOOKUP(K96,'справочник ножек'!A:B,2,FALSE) -> Черные ножки | I96: =CONCATENATE(F96," ",G96," ",H96) -> Комплект Стул Классика Melon Черные ножки | J96: К101 | K96: 3 | L96: =CONCATENATE(J96,G96,K96) -> К101Melon3 | M96: Стул/сиденье | N96: =F96 -> Комплект Стул Классика
A97: WB | B97: CT101MEL4K | C97: Комплект 2 стульев Классика | D97: 100000000 | E97: 2036830564595 | F97: Комплект Стул Классика | G97: Melon | H97: =VLOOKUP(K97,'справочник ножек'!A:B,2,FALSE) -> Черные ножки с наконечниками | I97: =CONCATENATE(F97," ",G97," ",H97) -> Комплект Стул Классика Melon Черные ножки с наконечниками | J97: К101 | K97: 4 | L97: =CONCATENATE(J97,G97,K97) -> К101Melon4 | M97: Стул/сиденье | N97: =F97 -> Комплект Стул Классика
A98: WB | B98: CT101BLU1K | C98: Комплект 2 стульев Классика | D98: 100000000 | E98: 2036830946414 | F98: Комплект Стул Классика | G98: Blue | H98: =VLOOKUP(K98,'справочник ножек'!A:B,2,FALSE) -> Коричневые ножки | I98: =CONCATENATE(F98," ",G98," ",H98) -> Комплект Стул Классика Blue Коричневые ножки | J98: К101 | K98: 1 | L98: =CONCATENATE(J98,G98,K98) -> К101Blue1 | M98: Стул/сиденье | N98: =F98 -> Комплект Стул Классика
... A131: WB | B131: CT101MIN77K | C131: Комплект 2 стульев Классика | D131: 100000000 | E131: 2036851363252 | F131: Комплект Стул Классика | G131: Mint | H131: =VLOOKUP(K131,'справочник ножек'!A:B,2,FALSE) -> Ножки патина серебро | I131: =CONCATENATE(F131," ",G131," ",H131) -> Комплект Стул Классика Mint Ножки патина серебро | J131: К101 | K131: 7 | L131: =CONCATENATE(J131,G131,K131) -> К101Mint7 | M131: Стул/сиденье | N131: =F131 -> Комплект Стул Классика
A132: WB | B132: CT101BER111 | C132: Стул/сиденье Классика | D132: 100000000 | E132: 2036862183719 | F132: Стул Классика | G132: Berry | H132: =VLOOKUP(K132,'справочник ножек'!A:B,2,FALSE) -> Коричневые ножки | I132: =CONCATENATE(F132," ",G132," ",H132) -> Стул Классика Berry Коричневые ножки | J132: 101 | K132: 1 | L132: =CONCATENATE(J132,G132,K132) -> 101Berry1 | M132: Стул/сиденье | N132: =F132 -> Стул Классика
A133: WB | B133: CT101BER333 | C133: Стул/сиденье Классика | D133: 100000000 | E133: 2036862522297 | F133: Стул Классика | G133: Berry | H133: =VLOOKUP(K133,'справочник ножек'!A:B,2,FALSE) -> Черные ножки | I133: =CONCATENATE(F133," ",G133," ",H133) -> Стул Классика Berry Черные ножки | J133: 101 | K133: 3 | L133: =CONCATENATE(J133,G133,K133) -> 101Berry3 | M133: Стул/сиденье | N133: =F133 -> Стул Классика
A134: WB | B134: CT101BIR111 | C134: Стул/сиденье Классика | D134: 100000000 | E134: 2036862545180 | F134: Стул Классика | G134: Biruza | H134: =VLOOKUP(K134,'справочник ножек'!A:B,2,FALSE) -> Коричневые ножки | I134: =CONCATENATE(F134," ",G134," ",H134) -> Стул Классика Biruza Коричневые ножки | J134: 101 | K134: 1 | L134: =CONCATENATE(J134,G134,K134) -> 101Biruza1 | M134: Стул/сиденье | N134: =F134 -> Стул Классика
A135: WB | B135: CT101BIR222 | C135: Стул/сиденье Классика | D135: 100000000 | E135: 2036862565225 | F135: Стул Классика | G135: Biruza | H135: =VLOOKUP(K135,'справочник ножек'!A:B,2,FALSE) -> Белые ножки | I135: =CONCATENATE(F135," ",G135," ",H135) -> Стул Классика Biruza Белые ножки | J135: 101 | K135: 2 | L135: =CONCATENATE(J135,G135,K135) -> 101Biruza2 | M135: Стул/сиденье | N135: =F135 -> Стул Классика
A136: WB | B136: CT101BIR333 | C136: Стул/сиденье Классика | D136: 100000000 | E136: 2036862584424 | F136: Стул Классика | G136: Biruza | H136: =VLOOKUP(K136,'справочник ножек'!A:B,2,FALSE) -> Черные ножки | I136: =CONCATENATE(F136," ",G136," ",H136) -> Стул Классика Biruza Черные ножки | J136: 101 | K136: 3 | L136: =CONCATENATE(J136,G136,K136) -> 101Biruza3 | M136: Стул/сиденье | N136: =F136 -> Стул Классика
A137: WB | B137: CT101BIR555 | C137: Стул/сиденье Классика | D137: 100000000 | E137: 2036862653533 | F137: Стул Классика | G137: Biruza | H137: =VLOOKUP(K137,'справочник ножек'!A:B,2,FALSE) -> Ножки прозрачный лак | I137: =CONCATENATE(F137," ",G137," ",H137) -> Стул Классика Biruza Ножки прозрачный лак | J137: 101 | K137: 5 | L137: =CONCATENATE(J137,G137,K137) -> 101Biruza5 | M137: Стул/сиденье | N137: =F137 -> Стул Классика
A138: WB | B138: CT101BIR888 | C138: Стул/сиденье Классика | D138: 100000000 | E138: 2036862671377 | F138: Стул Классика | G138: Biruza | H138: =VLOOKUP(K138,'справочник ножек'!A:B,2,FALSE) -> Ножки слоновая кость | I138: =CONCATENATE(F138," ",G138," ",H138) -> Стул Классика Biruza Ножки слоновая кость | J138: 101 | K138: 8 | L138: =CONCATENATE(J138,G138,K138) -> 101Biruza8 | M138: Стул/сиденье | N138: =F138 -> Стул Классика
A139: WB | B139: CT101BLU111 | C139: Стул/сиденье Классика | D139: 100000000 | E139: 2036862737677 | F139: Стул Классика | G139: Blue | H139: =VLOOKUP(K139,'справочник ножек'!A:B,2,FALSE) -> Коричневые ножки | I139: =CONCATENATE(F139," ",G139," ",H139) -> Стул Классика Blue Коричневые ножки | J139: 101 | K139: 1 | L139: =CONCATENATE(J139,G139,K139) -> 101Blue1 | M139: Стул/сиденье | N139: =F139 -> Стул Классика
A140: WB | B140: CT101BLU222 | C140: Стул/сиденье Классика | D140: 100000000 | E140: 2036862769302 | F140: Стул Классика | G140: Blue | H140: =VLOOKUP(K140,'справочник ножек'!A:B,2,FALSE) -> Белые ножки | I140: =CONCATENATE(F140," ",G140," ",H140) -> Стул Классика Blue Белые ножки | J140: 101 | K140: 2 | L140: =CONCATENATE(J140,G140,K140) -> 101Blue2 | M140: Стул/сиденье | N140: =F140 -> Стул Классика
A141: WB | B141: CT101BLU333 | C141: Стул/сиденье Классика | D141: 100000000 | E141: 2036862779752 | F141: Стул Классика | G141: Blue | H141: =VLOOKUP(K141,'справочник ножек'!A:B,2,FALSE) -> Черные ножки | I141: =CONCATENATE(F141," ",G141," ",H141) -> Стул Классика Blue Черные ножки | J141: 101 | K141: 3 | L141: =CONCATENATE(J141,G141,K141) -> 101Blue3 | M141: Стул/сиденье | N141: =F141 -> Стул Классика
A142: WB | B142: CT101BLU444 | C142: Стул/сиденье Классика | D142: 100000000 | E142: 2036862806052 | F142: Стул Классика | G142: Blue | H142: =VLOOKUP(K142,'справочник ножек'!A:B,2,FALSE) -> Черные ножки с наконечниками | I142: =CONCATENATE(F142," ",G142," ",H142) -> Стул Классика Blue Черные ножки с наконечниками | J142: 101 | K142: 4 | L142: =CONCATENATE(J142,G142,K142) -> 101Blue4 | M142: Стул/сиденье | N142: =F142 -> Стул Классика
...

Sheet справочник ножек
A1: Номер цвета ножек | B1: Ножки | E1: Цвет ткани
A2: 1 | B2: Коричневые ножки
A3: 2 | B3: Белые ножки
A4: 3 | B4: Черные ножки
A5: 7 | B5: Ножки патина серебро
A6: 5 | B6: Ножки прозрачный лак
A7: 8 | B7: Ножки слоновая кость
A8: 4 | B8: Черные ножки с наконечниками
A9: 6 | B9: Ножки золотая патина
A10: 9 | B10: Ножки слоновая кость с наконечниками
A11: 10 | B11: Белые ножки с наконечниками
A12: 11 | B12: Коричневые ножки с наконечниками
A13: 0 | B13: Без ножек
... A16: 14 | B16: Ножки зеленые

Sheet Для проверки коррекного заполн
A1: Обязательно внести номер позиции, после этого обновлять своды
A3: Номер позиции | B3: Тип изделия | D3: Цвет ткани | F3: Номер цвета ножек | G3: Ножки | I3: Номер позиции | J3: Предмет для расчета ЗП
A4: 101 | B4: Сиденье стула Классика | D4: Beige | F4: 0 | G4: Без ножек | I4: 101 | J4: Стул/сиденье
B5: Стул Классика | D5: Berry | F5: 1 | G5: Коричневые ножки | I5: 102 | J5: Диван/сиденье
A6: 102 | B6: Диван классика | D6: Biruza | F6: 2 | G6: Белые ножки | I6: 103 | J6: Стул/сиденье
B7: Сиденье дивана классика | D7: Blue | F7: 3 | G7: Черные ножки | I7: 104 | J7: Диван/сиденье
A8: 103 | B8: Сиденье стула с высокой спинкой | D8: Broun | F8: 4 | G8: Черные ножки с наконечниками | I8: 105 | J8: Стул/сиденье
A9: 104 | B9: Сиденье кушетки | D9: Coffe | F9: 5 | G9: Ножки прозрачный лак | I9: 106 | J9: Табурет
A10: 105 | B10: Сиденье стула Ракушка | D10: Coral | F10: 6 | G10: Ножки золотая патина | I10: 107 | J10: Стул/сиденье
B11: Стул Ракушка | D11: Cream | F11: 7 | G11: Ножки патина серебро | I11: 109 | J11: Диван/сиденье
A12: 106 | B12: Блинчик | D12: Cuppuccino | F12: 8 | G12: Ножки слоновая кость | I12: 110 | J12: Стул с подлокотниками
B13: Табурет | D13: Flamingo | F13: 9 | G13: Ножки слоновая кость с наконечниками | I13: 111 | J13: Стул/сиденье
A14: 107 | B14: Барный стул | D14: Forest | F14: 10 | G14: Белые ножки с наконечниками | I14: 113 | J14: Стул/сиденье
B15: Сиденье полубарного стула классика | D15: Graphite | F15: 11 | G15: Коричневые ножки с наконечниками | I15: 118 | J15: Табурет
A16: 109 | B16: Диван Ракушка | D16: Graphite&Melon | F16: 12 | G16: Ножки красные | I16: 120 | J16: Сидушка на стул
B17: Сиденье дивана Ракушка | D17: Koriza | F17: 13 | G17: Ножки синие | I17: 101 и 102 | J17: 2 стула + диван
A18: 110 | B18: Стул с подлокотниками | D18: Latte | F18: 14 | G18: Ножки зеленые | I18: 116/1 | J18: Стул детский
A19: 111 | B19: Стул полубарный с кольцом | D19: Melon | F19: (пусто) | G19: (пусто) | I19: 116/2 | J19: Стул детский
A20: 113 | B20: Сиденье полубарного стула Ракушка | D20: Melon&Graphite | F20: Общий итог | I20: 116/3 | J20: Стул детский
A21: 118 | B21: Табурет детский | D21: Mint | I21: 117/1 | J21: Стул детский
A22: 120 | B22: Подушка для стула | D22: Monsoon | I22: 117/2 | J22: Стул детский
A23: 101 и 102 | B23: 2 стула + диван | D23: Ocean | I23: 117/3 | J23: Стул детский
A24: 116/1 | B24: Стул детский Непоседа Трапеция Маленький | D24: Oliva | I24: CT1 | J24: Образец ткани
A25: 116/2 | B25: Стул детский Непоседа Трапеция Средний | D25: Orange | I25: К101 | J25: Стул/сиденье
A26: 116/3 | B26: Стул детский Непоседа Трапеция Высокий | D26: Sky | I26: (пусто) | J26: Образец ткани
A27: 117/1 | B27: Стул детский Сердце маленький | D27: Smoke | J27: (пусто)
A28: 117/2 | B28: Стул детский Сердце средний | D28: Teddi | I28: 40 | J28: Ножки
A29: 117/3 | B29: Стул детский Сердце большой | D29: Все цвета | I29: 60 | J29: Ножки
A30: CT1 | B30: Образцы ткани | D30: Цвет на выбор | I30: 340 | J30: Ножки
A31: К101 | B31: Комплект Стул Классика | D31: (пусто) | I31: К105 | J31: Стул/сиденье
A32: (пусто) | B32: Образцы ткани | D32: Общий итог | I32: Общий итог
B33: (пусто)
A34: 40 | B34: Ножки 40
A35: 60 | B35: Ножки 60
A36: 340 | B36: Ножки 40 3 шт
A37: К105 | B37: Комплект Стула Ракушка
A38: Общий итог
